Workbook
Name Conv: _xlfn.LAMBDA(_xlpm.deg,_xlpm.min,_xlpm.sec,_xlpm.dir,IF(OR(_xlpm.dir="S",_xlpm.dir="W"), -(_xlpm.deg + _xlpm.min/60 + _xlpm.sec/3600), _xlpm.deg + _xlpm.min/60 + _xlpm.sec/3600 ) )

Sheet Modern
A1: Country | B1: Area | C1: AreaRank | D1: Pop | E1: PopRank | F1: Independence | G1: Year | H1: YearRank | I1: Capital | J1: CapPop | K1: CapPopRank | L1: Density | M1: DensRank | N1: CityShare | O1: ShareRank | P1: Continent | Q1: Begin | R1: End | S1: NameChanges
A2: Singapore | B2: 284 | C2: =RANK(B2,B$2:B$197) -> 176 | D2: 6158000 | E2: =RANK(D2,D$2:D$197) -> 115 | F2: 1965-08-09 | G2: 1965 | H2: =RANK(G2,G$2:G$197) -> 73 | I2: Singapore | J2: 6158000 | K2: =RANK(J2,J$2:J$197) -> 20 | L2: =D2/B2 -> 21683.099 | M2: =RANK(L2,L$2:L$197) -> 2 | N2: =J2/D2 -> 1 | O2: =RANK(N2,N$2:N$197) -> 1 | P2: Asia | Q2: 1965 | R2: 2026
A3: Vatican City | B3: 0.19 | C3: =RANK(B3,B$2:B$197) -> 196 | D3: 882 | E3: =RANK(D3,D$2:D$197) -> 196 | F3: 1929-02-11 | G3: 1929 | H3: =RANK(G3,G$2:G$197) -> 137 | I3: Vatican City | J3: 882 | K3: =RANK(J3,J$2:J$197) -> 194 | L3: =D3/B3 -> 4642.1053 | M3: =RANK(L3,L$2:L$197) -> 6 | N3: =J3/D3 -> 1 | O3: =RANK(N3,N$2:N$197) -> 1 | P3: Europe | Q3: 1929 | R3: 2026
A4: Bahamas | B4: 5382 | C4: =RANK(B4,B$2:B$197) -> 156 | D4: 413400 | E4: =RANK(D4,D$2:D$197) -> 172 | F4: 1973-07-10 | G4: 1973 | H4: =RANK(G4,G$2:G$197) -> 55 | I4: Nassau | J4: 296522 | K4: =RANK(J4,J$2:J$197) -> 141 | L4: =D4/B4 -> 76.811594 | M4: =RANK(L4,L$2:L$197) -> 154 | N4: =J4/D4 -> 0.71727625 | O4: =RANK(N4,N$2:N$197) -> 3 | P4: North America | Q4: 1973 | R4: 2026
A5: Djibouti | B5: 8958 | C5: =RANK(B5,B$2:B$197) -> 147 | D5: 1088000 | E5: =RANK(D5,D$2:D$197) -> 158 | F5: 1977-06-27 | G5: 1977 | H5: =RANK(G5,G$2:G$197) -> 43 | I5: Djibouti City | J5: 776966 | K5: =RANK(J5,J$2:J$197) -> 104 | L5: =D5/B5 -> 121.45568 | M5: =RANK(L5,L$2:L$197) -> 138 | N5: =J5/D5 -> 0.71412316 | O5: =RANK(N5,N$2:N$197) -> 4 | P5: Africa | Q5: 1977 | R5: 2026
A6: Tuvalu | B6: 10.14 | C6: =RANK(B6,B$2:B$197) -> 193 | D6: 9700 | E6: =RANK(D6,D$2:D$197) -> 195 | F6: 1978-10-01 | G6: 1978 | H6: =RANK(G6,G$2:G$197) -> 40 | I6: Funafuti | J6: 6602 | K6: =RANK(J6,J$2:J$197) -> 188 | L6: =D6/B6 -> 956.6075 | M6: =RANK(L6,L$2:L$197) -> 23 | N6: =J6/D6 -> 0.68061856 | O6: =RANK(N6,N$2:N$197) -> 5 | P6: Oceania | Q6: 1978 | R6: 2026
A7: Kuwait | B7: 6880 | C7: =RANK(B7,B$2:B$197) -> 153 | D7: 5098000 | E7: =RANK(D7,D$2:D$197) -> 126 | F7: 1961-06-19 | G7: 1961 | H7: =RANK(G7,G$2:G$197) -> 90 | I7: Kuwait City | J7: 3405000 | K7: =RANK(J7,J$2:J$197) -> 31 | L7: =D7/B7 -> 740.98837 | M7: =RANK(L7,L$2:L$197) -> 33 | N7: =J7/D7 -> 0.66790898 | O7: =RANK(N7,N$2:N$197) -> 6 | P7: Asia | Q7: 1961 | R7: 2026
A8: Marshall Islands | B8: 70 | C8: =RANK(B8,B$2:B$197) -> 190 | D8: 38900 | E8: =RANK(D8,D$2:D$197) -> 190 | F8: 1979-05-01 | G8: 1979 | H8: =RANK(G8,G$2:G$197) -> 35 | I8: Majuro | J8: 23156 | K8: =RANK(J8,J$2:J$197) -> 180 | L8: =D8/B8 -> 555.71429 | M8: =RANK(L8,L$2:L$197) -> 48 | N8: =J8/D8 -> 0.59526992 | O8: =RANK(N8,N$2:N$197) -> 7 | P8: Oceania | Q8: 1979 | R8: 2026
A9: Kiribati | B9: 313 | C9: =RANK(B9,B$2:B$197) -> 173 | D9: 128800 | E9: =RANK(D9,D$2:D$197) -> 179 | F9: 1979-07-12 | G9: 1979 | H9: =RANK(G9,G$2:G$197) -> 35 | I9: Tarawa | J9: 70480 | K9: =RANK(J9,J$2:J$197) -> 170 | L9: =D9/B9 -> 411.5016 | M9: =RANK(L9,L$2:L$197) -> 57 | N9: =J9/D9 -> 0.54720497 | O9: =RANK(N9,N$2:N$197) -> 8 | P9: Oceania | Q9: 1979 | R9: 2026
A10: Mongolia | B10: 603908 | C10: =RANK(B10,B$2:B$197) -> 18 | D10: 3569000 | E10: =RANK(D10,D$2:D$197) -> 131 | F10: 1924-11-26 | G10: 1924 | H10: =RANK(G10,G$2:G$197) -> 138 | I10: Ulaanbaatar | J10: 1672627 | K10: =RANK(J10,J$2:J$197) -> 65 | L10: =D10/B10 -> 5.9098406 | M10: =RANK(L10,L$2:L$197) -> 196 | N10: =J10/D10 -> 0.46865424 | O10: =RANK(N10,N$2:N$197) -> 9 | P10: Asia | Q10: 1924 | R10: 2026
A11: Bahrain | B11: 304 | C11: =RANK(B11,B$2:B$197) -> 174 | D11: 1628000 | E11: =RANK(D11,D$2:D$197) -> 150 | F11: 1971-08-14 | G11: 1971 | H11: =RANK(G11,G$2:G$197) -> 57 | I11: Manama | J11: 743066 | K11: =RANK(J11,J$2:J$197) -> 109 | L11: =D11/B11 -> 5355.2632 | M11: =RANK(L11,L$2:L$197) -> 3 | N11: =J11/D11 -> 0.45642875 | O11: =RANK(N11,N$2:N$197) -> 10 | P11: Asia | Q11: 1971 | R11: 2026
A12: Barbados | B12: 167 | C12: =RANK(B12,B$2:B$197) -> 184 | D12: 264300 | E12: =RANK(D12,D$2:D$197) -> 175 | F12: 1966-11-30 | G12: 1966 | H12: =RANK(G12,G$2:G$197) -> 68 | I12: Bridgetown | J12: 110000 | K12: =RANK(J12,J$2:J$197) -> 163 | L12: =D12/B12 -> 1582.6347 | M12: =RANK(L12,L$2:L$197) -> 10 | N12: =J12/D12 -> 0.41619372 | O12: =RANK(N12,N$2:N$197) -> 11 | P12: North America | Q12: 1966 | R12: 2026
A13: Jordan | B13: 34284 | C13: =RANK(B13,B$2:B$197) -> 110 | D13: 11845000 | E13: =RANK(D13,D$2:D$197) -> 85 | F13: 1946-05-25 | G13: 1946 | H13: =RANK(G13,G$2:G$197) -> 127 | I13: Amman | J13: 4920100 | K13: =RANK(J13,J$2:J$197) -> 24 | L13: =D13/B13 -> 345.49644 | M13: =RANK(L13,L$2:L$197) -> 69 | N13: =J13/D13 -> 0.41537358 | O13: =RANK(N13,N$2:N$197) -> 12 | P13: Asia | Q13: 1946 | R13: 2026
... A89: Comoros | B89: 719 | C89: =RANK(B89,B$2:B$197) -> 171 | D89: 877400 | E89: =RANK(D89,D$2:D$197) -> 160 | F89: 1975-07-06 | G89: 1975 | H89: =RANK(G89,G$2:G$197) -> 46 | I89: Moroni | J89: 111326 | K89: =RANK(J89,J$2:J$197) -> 162 | L89: =D89/B89 -> 1220.306 | M89: =RANK(L89,L$2:L$197) -> 18 | N89: =J89/D89 -> 0.1268817 | O89: =RANK(N89,N$2:N$197) -> 88 | P89: Africa | Q89: 1975 | R89: 2026
A90: Thailand | B90: 198124 | C90: =RANK(B90,B$2:B$197) -> 49 | D90: 66220000 | E90: =RANK(D90,D$2:D$197) -> 23 | F90: 1932-06-24 | G90: 1932 | H90: =RANK(G90,G$2:G$197) -> 133 | I90: Bangkok | J90: 8305218 | K90: =RANK(J90,J$2:J$197) -> 15 | L90: =D90/B90 -> 334.23513 | M90: =RANK(L90,L$2:L$197) -> 70 | N90: =J90/D90 -> 0.12541857 | O90: =RANK(N90,N$2:N$197) -> 89 | P90: Asia | Q90: 1932 | R90: 2026 | S90: Changed from Siam in 1939
A91: Rwanda | B91: 10169 | C91: =RANK(B91,B$2:B$197) -> 145 | D91: 14105000 | E91: =RANK(D91,D$2:D$197) -> 78 | F91: 1962-07-01 | G91: 1962 | H91: =RANK(G91,G$2:G$197) -> 84 | I91: Kigali | J91: 1745555 | K91: =RANK(J91,J$2:J$197) -> 61 | L91: =D91/B91 -> 1387.0587 | M91: =RANK(L91,L$2:L$197) -> 14 | N91: =J91/D91 -> 0.12375434 | O91: =RANK(N91,N$2:N$197) -> 90 | P91: Africa | Q91: 1962 | R91: 2026
A92: Central African Republic | B92: 240324 | C92: =RANK(B92,B$2:B$197) -> 43 | D92: 6602000 | E92: =RANK(D92,D$2:D$197) -> 109 | F92: 1958-12-01 | G92: 1958 | H92: =RANK(G92,G$2:G$197) -> 107 | I92: Bangui | J92: 812407 | K92: =RANK(J92,J$2:J$197) -> 102 | L92: =D92/B92 -> 27.471247 | M92: =RANK(L92,L$2:L$197) -> 183 | N92: =J92/D92 -> 0.12305468 | O92: =RANK(N92,N$2:N$197) -> 91 | P92: Africa | Q92: 1958 | R92: 2026
A93: Finland | B93: 130692 | C93: =RANK(B93,B$2:B$197) -> 66 | D93: 5642000 | E93: =RANK(D93,D$2:D$197) -> 119 | F93: 1917-12-06 | G93: 1917 | H93: =RANK(G93,G$2:G$197) -> 143 | I93: Helsinki | J93: 689758 | K93: =RANK(J93,J$2:J$197) -> 115 | L93: =D93/B93 -> 43.170202 | M93: =RANK(L93,L$2:L$197) -> 176 | N93: =J93/D93 -> 0.12225417 | O93: =RANK(N93,N$2:N$197) -> 92 | P93: Europe | Q93: 1917 | R93: 2026
A94: San Marino | B94: 24 | C94: =RANK(B94,B$2:B$197) -> 192 | D94: 34100 | E94: =RANK(D94,D$2:D$197) -> 192 | F94: 1291-01-01 | G94: 1291 | H94: =RANK(G94,G$2:G$197) -> 189 | I94: San Marino | J94: 4118 | K94: =RANK(J94,J$2:J$197) -> 191 | L94: =D94/B94 -> 1420.8333 | M94: =RANK(L94,L$2:L$197) -> 12 | N94: =J94/D94 -> 0.12076246 | O94: =RANK(N94,N$2:N$197) -> 93 | P94: Europe | Q94: 1291 | R94: 2026
A95: North Korea | B95: 47573 | C95: =RANK(B95,B$2:B$197) -> 97 | D95: 26403000 | E95: =RANK(D95,D$2:D$197) -> 56 | F95: 1948-07-10 | G95: 1948 | H95: =RANK(G95,G$2:G$197) -> 120 | I95: Pyongyang | J95: 3157538 | K95: =RANK(J95,J$2:J$197) -> 35 | L95: =D95/B95 -> 554.99968 | M95: =RANK(L95,L$2:L$197) -> 49 | N95: =J95/D95 -> 0.11959012 | O95: =RANK(N95,N$2:N$197) -> 94 | P95: Asia | Q95: 1948 | R95: 2026
A96: Syria | B96: 71498 | C96: =RANK(B96,B$2:B$197) -> 87 | D96: 23607000 | E96: =RANK(D96,D$2:D$197) -> 59 | F96: 1963-03-08 | G96: 1963 | H96: =RANK(G96,G$2:G$197) -> 81 | I96: Damascus | J96: 2799960 | K96: =RANK(J96,J$2:J$197) -> 39 | L96: =D96/B96 -> 330.17707 | M96: =RANK(L96,L$2:L$197) -> 71 | N96: =J96/D96 -> 0.11860719 | O96: =RANK(N96,N$2:N$197) -> 95 | P96: Asia | Q96: 1963 | R96: 2026
A97: Tajikistan | B97: 54595 | C97: =RANK(B97,B$2:B$197) -> 94 | D97: 10576000 | E97: =RANK(D97,D$2:D$197) -> 92 | F97: 1991-09-09 | G97: 1991 | H97: =RANK(G97,G$2:G$197) -> 8 | I97: Dushanbe | J97: 1228400 | K97: =RANK(J97,J$2:J$197) -> 79 | L97: =D97/B97 -> 193.71737 | M97: =RANK(L97,L$2:L$197) -> 110 | N97: =J97/D97 -> 0.11614977 | O97: =RANK(N97,N$2:N$197) -> 96 | P97: Asia | Q97: 1991 | R97: 2026
A98: Japan | B98: 145937 | C98: =RANK(B98,B$2:B$197) -> 62 | D98: 123105000 | E98: =RANK(D98,D$2:D$197) -> 11 | F98: 710-01-01 | G98: 710 | H98: =RANK(G98,G$2:G$197) -> 194 | I98: Tokyo | J98: 14254039 | K98: =RANK(J98,J$2:J$197) -> 3 | L98: =D98/B98 -> 843.54893 | M98: =RANK(L98,L$2:L$197) -> 27 | N98: =J98/D98 -> 0.11578765 | O98: =RANK(N98,N$2:N$197) -> 97 | P98: Asia | Q98: 710 | R98: 2026
A99: Saint Vincent and the Grenadines | B99: 150 | C99: =RANK(B99,B$2:B$197) -> 185 | D99: 111600 | E99: =RANK(D99,D$2:D$197) -> 181 | F99: 1979-10-27 | G99: 1979 | H99: =RANK(G99,G$2:G$197) -> 35 | I99: Kingstown | J99: 12909 | K99: =RANK(J99,J$2:J$197) -> 186 | L99: =D99/B99 -> 744 | M99: =RANK(L99,L$2:L$197) -> 31 | N99: =J99/D99 -> 0.11567204 | O99: =RANK(N99,N$2:N$197) -> 98 | P99: North America | Q99: 1979 | R99: 2026
A100: Guinea | B100: 94926 | C100: =RANK(B100,B$2:B$197) -> 77 | D100: 14364000 | E100: =RANK(D100,D$2:D$197) -> 76 | F100: 1958-10-02 | G100: 1958 | H100: =RANK(G100,G$2:G$197) -> 107 | I100: Conakry | J100: 1660973 | K100: =RANK(J100,J$2:J$197) -> 66 | L100: =D100/B100 -> 151.31787 | M100: =RANK(L100,L$2:L$197) -> 125 | N100: =J100/D100 -> 0.11563443 | O100: =RANK(N100,N$2:N$197) -> 99 | P100: Africa | Q100: 1958 | R100: 2026
A101: Saint Lucia | B101: 242 | C101: =RANK(B101,B$2:B$197) -> 179 | D101: 174800 | E101: =RANK(D101,D$2:D$197) -> 178 | F101: 1979-02-22 | G101: 1979 | H101: =RANK(G101,G$2:G$197) -> 35 | I101: Castries | J101: 20000 | K101: =RANK(J101,J$2:J$197) -> 183 | L101: =D101/B101 -> 722.31405 | M101: =RANK(L101,L$2:L$197) -> 34 | N101: =J101/D101 -> 0.11441648 | O101: =RANK(N101,N$2:N$197) -> 100 | P101: North America | Q101: 1979 | R101: 2026
A102: Kenya | B102: 224961 | C102: =RANK(B102,B$2:B$197) -> 46 | D102: 53477000 | E102: =RANK(D102,D$2:D$197) -> 28 | F102: 1964-12-12 | G102: 1964 | H102: =RANK(G102,G$2:G$197) -> 77 | I102: Nairobi | J102: 6100000 | K102: =RANK(J102,J$2:J$197) -> 21 | L102: =D102/B102 -> 237.71676 | M102: =RANK(L102,L$2:L$197) -> 96 | N102: =J102/D102 -> 0.11406773 | O102: =RANK(N102,N$2:N$197) -> 101 | P102: Africa | Q102: 1964 | R102: 2026
... A113: Ecuador | B113: 99170 | C113: =RANK(B113,B$2:B$197) -> 76 | D113: 17573000 | E113: =RANK(D113,D$2:D$197) -> 72 | F113: 1830-05-13 | G113: 1830 | H113: =RANK(G113,G$2:G$197) -> 167 | I113: Quito | J113: 1763275 | K113: =RANK(J113,J$2:J$197) -> 59 | L113: =D113/B113 -> 177.20077 | M113: =RANK(L113,L$2:L$197) -> 119 | N113: =J113/D113 -> 0.10034001 | O113: =RANK(N113,N$2:N$197) -> 112 | P113: South America | Q113: 1830 | R113: 2026
A114: Burkina Faso | B114: 104543 | C114: =RANK(B114,B$2:B$197) -> 73 | D114: 24071000 | E114: =RANK(D114,D$2:D$197) -> 58 | F114: 1960-08-05 | G114: 1960 | H114: =RANK(G114,G$2:G$197) -> 92 | I114: Ouagadougou | J114: 2415266 | K114: =RANK(J114,J$2:J$197) -> 43 | L114: =D114/B114 -> 230.24975 | M114: =RANK(L114,L$2:L$197) -> 100 | N114: =J114/D114 -> 0.10033925 | O114: =RANK(N114,N$2:N$197) -> 113 | P114: Africa | Q114: 1960 | R114: 2026 | S114: Changed from Upper Volta 1984
A115: Botswana | B115: 220141 | C115: =RANK(B115,B$2:B$197) -> 47 | D115: 2475000 | E115: =RANK(D115,D$2:D$197) -> 141 | F115: 1966-09-30 | G115: 1966 | H115: =RANK(G115,G$2:G$197) -> 68 | I115: Gabarone | J115: 246325 | K115: =RANK(J115,J$2:J$197) -> 148 | L115: =D115/B115 -> 11.242794 | M115: =RANK(L115,L$2:L$197) -> 189 | N115: =J115/D115 -> 0.099525253 | O115: =RANK(N115,N$2:N$197) -> 114 | P115: Africa | Q115: 1966 | R115: 2026
A116: Romania | B116: 92046 | C116: =RANK(B116,B$2:B$197) -> 81 | D116: 19079000 | E116: =RANK(D116,D$2:D$197) -> 69 | F116: 1877-05-10 | G116: 1877 | H116: =RANK(G116,G$2:G$197) -> 153 | I116: Bucharest | J116: 1877155 | K116: =RANK(J116,J$2:J$197) -> 56 | L116: =D116/B116 -> 207.2768 | M116: =RANK(L116,L$2:L$197) -> 105 | N116: =J116/D116 -> 0.098388542 | O116: =RANK(N116,N$2:N$197) -> 115 | P116: Europe | Q116: 1877 | R116: 2026
A117: Egypt | B117: 384790 | C117: =RANK(B117,B$2:B$197) -> 29 | D117: 107838000 | E117: =RANK(D117,D$2:D$197) -> 15 | F117: 1922-02-28 | G117: 1922 | H117: =RANK(G117,G$2:G$197) -> 141 | I117: Cairo | J117: 10500000 | K117: =RANK(J117,J$2:J$197) -> 6 | L117: =D117/B117 -> 280.25157 | M117: =RANK(L117,L$2:L$197) -> 81 | N117: =J117/D117 -> 0.097368275 | O117: =RANK(N117,N$2:N$197) -> 116 | P117: Africa | Q117: 1922 | R117: 2026
A118: Haiti | B118: 10450 | C118: =RANK(B118,B$2:B$197) -> 144 | D118: 12562000 | E118: =RANK(D118,D$2:D$197) -> 81 | F118: 1825-04-17 | G118: 1825 | H118: =RANK(G118,G$2:G$197) -> 170 | I118: Port-au-Prince | J118: 1200000 | K118: =RANK(J118,J$2:J$197) -> 81 | L118: =D118/B118 -> 1202.1053 | M118: =RANK(L118,L$2:L$197) -> 19 | N118: =J118/D118 -> 0.09552619 | O118: =RANK(N118,N$2:N$197) -> 117 | P118: North America | Q118: 1825 | R118: 2026
A119: Sweden | B119: 172751 | C119: =RANK(B119,B$2:B$197) -> 56 | D119: 10577000 | E119: =RANK(D119,D$2:D$197) -> 91 | F119: 1523-06-06 | G119: 1523 | H119: =RANK(G119,G$2:G$197) -> 187 | I119: Stockholm | J119: 996264 | K119: =RANK(J119,J$2:J$197) -> 96 | L119: =D119/B119 -> 61.226853 | M119: =RANK(L119,L$2:L$197) -> 165 | N119: =J119/D119 -> 0.094191548 | O119: =RANK(N119,N$2:N$197) -> 118 | P119: Europe | Q119: 1523 | R119: 2026
A120: Venezuela | B120: 353841 | C120: =RANK(B120,B$2:B$197) -> 32 | D120: 34464000 | E120: =RANK(D120,D$2:D$197) -> 43 | F120: 1830-01-13 | G120: 1830 | H120: =RANK(G120,G$2:G$197) -> 167 | I120: Caracas | J120: 3242000 | K120: =RANK(J120,J$2:J$197) -> 33 | L120: =D120/B120 -> 97.39968 | M120: =RANK(L120,L$2:L$197) -> 146 | N120: =J120/D120 -> 0.094069174 | O120: =RANK(N120,N$2:N$197) -> 119 | P120: South America | Q120: 1830 | R120: 2026
A121: Panama | B121: 29037 | C121: =RANK(B121,B$2:B$197) -> 115 | D121: 4379000 | E121: =RANK(D121,D$2:D$197) -> 128 | F121: 1903-11-03 | G121: 1903 | H121: =RANK(G121,G$2:G$197) -> 148 | I121: Panama City | J121: 410354 | K121: =RANK(J121,J$2:J$197) -> 137 | L121: =D121/B121 -> 150.80759 | M121: =RANK(L121,L$2:L$197) -> 128 | N121: =J121/D121 -> 0.093709523 | O121: =RANK(N121,N$2:N$197) -> 120 | P121: North America | Q121: 1903 | R121: 2026
A122: Zimbabwe | B122: 150872 | C122: =RANK(B122,B$2:B$197) -> 60 | D122: 15952000 | E122: =RANK(D122,D$2:D$197) -> 74 | F122: 1965-11-11 | G122: 1965 | H122: =RANK(G122,G$2:G$197) -> 73 | I122: Harare | J122: 1491740 | K122: =RANK(J122,J$2:J$197) -> 69 | L122: =D122/B122 -> 105.73201 | M122: =RANK(L122,L$2:L$197) -> 145 | N122: =J122/D122 -> 0.093514293 | O122: =RANK(N122,N$2:N$197) -> 121 | P122: Africa | Q122: 1965 | R122: 2026 | S122: Changed from Rhodesia 1980
A123: Dominican Republic | B123: 18619 | C123: =RANK(B123,B$2:B$197) -> 128 | D123: 11074000 | E123: =RANK(D123,D$2:D$197) -> 87 | F123: 1844-02-27 | G123: 1844 | H123: =RANK(G123,G$2:G$197) -> 161 | I123: Santo Domingo | J123: 1029110 | K123: =RANK(J123,J$2:J$197) -> 92 | L123: =D123/B123 -> 594.76878 | M123: =RANK(L123,L$2:L$197) -> 46 | N123: =J123/D123 -> 0.092930287 | O123: =RANK(N123,N$2:N$197) -> 122 | P123: North America | Q123: 1844 | R123: 2026
A124: Algeria | B124: 919595 | C124: =RANK(B124,B$2:B$197) -> 10 | D124: 47803000 | E124: =RANK(D124,D$2:D$197) -> 32 | F124: 1962-07-05 | G124: 1962 | H124: =RANK(G124,G$2:G$197) -> 84 | I124: Algiers | J124: 4325000 | K124: =RANK(J124,J$2:J$197) -> 25 | L124: =D124/B124 -> 51.982666 | M124: =RANK(L124,L$2:L$197) -> 168 | N124: =J124/D124 -> 0.090475493 | O124: =RANK(N124,N$2:N$197) -> 123 | P124: Africa | Q124: 1962 | R124: 2026
A125: Russia | B125: 6592846 | C125: =RANK(B125,B$2:B$197) -> 1 | D125: 145335000 | E125: =RANK(D125,D$2:D$197) -> 9 | F125: 1991-12-12 | G125: 1991 | H125: =RANK(G125,G$2:G$197) -> 8 | I125: Moscow | J125: 13010012 | K125: =RANK(J125,J$2:J$197) -> 4 | L125: =D125/B125 -> 22.044349 | M125: =RANK(L125,L$2:L$197) -> 185 | N125: =J125/D125 -> 0.089517405 | O125: =RANK(N125,N$2:N$197) -> 124 | P125: Europe | Q125: 1991 | R125: 2026
...

Sheet Sovereignty
A1: Polity | B1: Name | C1: Begin | D1: End | E1: Color | F1: Type | G1: Parent | H1: Continent | I1: Predecessor | J1: Country | K1: Filter | L1: Checked | M1: LegacyName | N1: LegacyCaps | O1: Sort | P1: Year => | Q1: =S509 -> 20260101
A2: DJI_1977 | B2: Djibouti | C2: 19770627 | D2: 20261231 | E2: #e41a1c | F2: Sovereign | H2: Africa | I2: DJI_1967_FRA | J2: =IF( F2 = "Sovereign", "x", "" ) -> x | K2: =( $C2<=$Q$1 )*( $D2 > $Q$1 ) * 1 -> 1 | L2: x | O2: 1
A3: DJI_1862_FRA | B3: Djibouti | C3: 18620311 | D3: 19770627 | E3: #BFE6FF | F3: Dependent | G3: France | H3: Africa | I3: NA | K3: =( $C3<=$Q$1 )*( $D3 > $Q$1 ) * 1 -> 0 | L3: x | O3: 2
A4: SOM_1960 | B4: Somalia | C4: 19600626 | D4: 20261231 | E4: #377eb8 | F4: Sovereign | H4: Africa | I4: SOM_1950_ITA/SOL_1884_UK | J4: =IF( F4 = "Sovereign", "x", "" ) -> x | K4: =( $C4<=$Q$1 )*( $D4 > $Q$1 ) * 1 -> 1 | L4: x | M4: Federal Republic of Somalia | N4: Mogadishu | O4: 3
A5: SOL_1884_UK | B5: British Somaliland | C5: 18840101 | D5: 19600626 | E5: #FFEEBA | F5: Dependent | G5: United Kingdom | H5: Africa | I5: NA | J5: =IF( F5 = "Sovereign", "x", "" ) | K5: =( $C5<=$Q$1 )*( $D5 > $Q$1 ) * 1 -> 0 | L5: x | M5: Somaliland Protectorate | N5: Berbera | O5: 4
A6: SOM_1950_ITA | B6: Somaliland | C6: 19500401 | D6: 19600701 | E6: #B9B9B9 | F6: Dependent | G6: Italy | H6: Africa | I6: SOM_1941_UK | K6: =( $C6<=$Q$1 )*( $D6 > $Q$1 ) * 1 -> 0 | L6: x | O6: 5
A7: SOM_1941_UK | B7: Somaliland | C7: 19410225 | D7: 19500401 | E7: #FFEEBA | F7: Dependent | G7: United Kingdom | H7: Africa | I7: IEA_1936_ITA | J7: =IF( F7 = "Sovereign", "x", "" ) | K7: =( $C7<=$Q$1 )*( $D7 > $Q$1 ) * 1 -> 0 | L7: x | O7: 6
A8: IEA_1936_ITA | B8: Italian East Africa | C8: 19360509 | D8: 19411127 | E8: #B9B9B9 | F8: Dependent | G8: Italy | H8: Africa | I8: ERI_1882_ITA/ETH_1855/SOM_1889_ITA/SOL_1884_UK | J8: =IF( F8 = "Sovereign", "x", "" ) | K8: =( $C8<=$Q$1 )*( $D8 > $Q$1 ) * 1 -> 0 | L8: x | M8: Italian East Africa | N8: Addis Ababa | O8: 7
A9: SOM_1889_ITA | B9: Italian Somaliland | C9: 18890208 | D9: 19360601 | E9: #B9B9B9 | F9: Dependent | G9: Italy | H9: Africa | I9: NA | J9: =IF( F9 = "Sovereign", "x", "" ) | K9: =( $C9<=$Q$1 )*( $D9 > $Q$1 ) * 1 -> 0 | L9: x | M9: Italian Somaliland | N9: Mogadiscio | O9: 8
A10: ERI_1993 | B10: Eritrea | C10: 19930524 | D10: 20261231 | E10: #4daf4a | F10: Sovereign | H10: Africa | I10: ETH_1941 | J10: =IF( F10 = "Sovereign", "x", "" ) -> x | K10: =( $C10<=$Q$1 )*( $D10 > $Q$1 ) * 1 -> 1 | L10: x | M10: State of Eritrea | N10: Asmara | O10: 9
A11: ERI_1952 | B11: Eritrea | C11: 19520915 | D11: 19621114 | E11: #984ea3 | F11: Sovereign | H11: Africa | I11: ETH_1941 | J11: =IF( F11 = "Sovereign", "x", "" ) -> x | K11: =( $C11<=$Q$1 )*( $D11 > $Q$1 ) * 1 -> 0 | L11: x | M11: Province of Eritrea | N11: Asmara | O11: 10
A12: ERI_1941_UK | B12: Eritrea | C12: 19411127 | D12: 19520915 | E12: #FFEEBA | F12: Dependent | G12: United Kingdom | H12: Africa | I12: IEA_1936_ITA | J12: =IF( F12 = "Sovereign", "x", "" ) | K12: =( $C12<=$Q$1 )*( $D12 > $Q$1 ) * 1 -> 0 | L12: x | M12: British Military Administration in Eritrea | N12: Asmara | O12: 11
A13: ERI_1882_ITA | B13: Italian Eritrea | C13: 18820705 | D13: 19360601 | E13: #B9B9B9 | F13: Dependent | G13: Italy | H13: Africa | I13: ETH_1855 | J13: =IF( F13 = "Sovereign", "x", "" ) | K13: =( $C13<=$Q$1 )*( $D13 > $Q$1 ) * 1 -> 0 | L13: x | M13: Colony of Eritrea | N13: Asmara | O13: 12
A14: ETH_1941 | B14: Ethiopia | C14: 19411127 | D14: 20261231 | E14: #ff7f00 | F14: Sovereign | H14: Africa | I14: IEA_1936_ITA | J14: =IF( F14 = "Sovereign", "x", "" ) -> x | K14: =( $C14<=$Q$1 )*( $D14 > $Q$1 ) * 1 -> 1 | L14: x | M14: Federal Democratic Republic of Eritrea | N14: Addis Ababa | O14: 13
A15: ETH_1855 | B15: Ethiopia | C15: 18550211 | D15: 19360509 | E15: #ffff33 | F15: Sovereign | H15: Africa | I15: NA | J15: =IF( F15 = "Sovereign", "x", "" ) -> x | K15: =( $C15<=$Q$1 )*( $D15 > $Q$1 ) * 1 -> 0 | L15: x | M15: Ethiopian Empire | N15: Addis Ababa | O15: 14
A16: CON_1960 | B16: Republic of the Congo | C16: 19600815 | D16: 20261231 | E16: #a65628 | F16: Sovereign | H16: Africa | I16: CON_1958_FRA | J16: =IF( F16 = "Sovereign", "x", "" ) -> x | K16: =( $C16<=$Q$1 )*( $D16 > $Q$1 ) * 1 -> 1 | L16: x | M16: Republic of the Congo | N16: Brazzaville | O16: 15
A17: CON_1958_FRA | B17: Republic of the Congo | C17: 19581128 | D17: 19600815 | E17: #BFE6FF | F17: Dependent | G17: France | H17: Africa | I17: FEA_1910_FRA | J17: =IF( F17 = "Sovereign", "x", "" ) | K17: =( $C17<=$Q$1 )*( $D17 > $Q$1 ) * 1 -> 0 | L17: x | M17: Republic of the Congo | N17: Brazzaville | O17: 16
A18: FEA_1910_FRA | B18: French Equatorial Africa | C18: 19100115 | D18: 19581128 | E18: #BFE6FF | F18: Dependent | G18: France | H18: Africa | I18: CON_1882_FRA/GAB_1885_FRA/CAR_1903_FRA/CHD_1900_FRA | J18: =IF( F18 = "Sovereign", "x", "" ) | K18: =( $C18<=$Q$1 )*( $D18 > $Q$1 ) * 1 -> 0 | L18: x | M18: French Equatorial Africa | N18: Brazzaville | O18: 17
A19: CON_1882_FRA | B19: French Congo | C19: 18821130 | D19: 19100115 | E19: #BFE6FF | F19: Dependent | G19: France | H19: Africa | I19: NA | J19: =IF( F19 = "Sovereign", "x", "" ) | K19: =( $C19<=$Q$1 )*( $D19 > $Q$1 ) * 1 -> 0 | L19: x | M19: French Congo | N19: Brazzaville | O19: 18
A20: GAB_1960 | B20: Gabon | C20: 19600817 | D20: 20261231 | E20: #f781bf | F20: Sovereign | H20: Africa | I20: GAB_1958_FRA | J20: =IF( F20 = "Sovereign", "x", "" ) -> x | K20: =( $C20<=$Q$1 )*( $D20 > $Q$1 ) * 1 -> 1 | L20: x | M20: Republic of Gabon | N20: Libreville | O20: 19
A21: GAB_1958_FRA | B21: French Gabon | C21: 19581128 | D21: 19600817 | E21: #BFE6FF | F21: Dependent | G21: France | H21: Africa | I21: FEA_1910_FRA | J21: =IF( F21 = "Sovereign", "x", "" ) | K21: =( $C21<=$Q$1 )*( $D21 > $Q$1 ) * 1 -> 0 | L21: x | M21: Republic of Gabon | N21: Libreville | O21: 20
A22: GAB_1885_FRA | B22: French Gabon | C22: 18850101 | D22: 19100115 | E22: #BFE6FF | F22: Dependent | G22: France | H22: Africa | I22: NA | J22: =IF( F22 = "Sovereign", "x", "" ) | K22: =( $C22<=$Q$1 )*( $D22 > $Q$1 ) * 1 -> 0 | L22: x | M22: Colony of Gabon | N22: Libreville | O22: 21
A23: CAR_1960 | B23: Central African Republic | C23: 19600813 | D23: 20261231 | E23: #999999 | F23: Sovereign | H23: Africa | I23: CAR_1958_FRA | J23: =IF( F23 = "Sovereign", "x", "" ) -> x | K23: =( $C23<=$Q$1 )*( $D23 > $Q$1 ) * 1 -> 1 | L23: x | M23: Central African Republic | N23: Bangui | O23: 22
A24: CAR_1958_FRA | B24: Central African Republic | C24: 19581201 | D24: 19600813 | E24: #BFE6FF | F24: Dependent | G24: France | H24: Africa | I24: FEA_1910_FRA | J24: =IF( F24 = "Sovereign", "x", "" ) | K24: =( $C24<=$Q$1 )*( $D24 > $Q$1 ) * 1 -> 0 | L24: x | M24: Central African Republic | N24: Bangui | O24: 23
A25: CAR_1903_FRA | B25: Ubangi-Shari | C25: 19031229 | D25: 19100115 | E25: #BFE6FF | F25: Dependent | G25: France | H25: Africa | I25: NA | J25: =IF( F25 = "Sovereign", "x", "" ) | K25: =( $C25<=$Q$1 )*( $D25 > $Q$1 ) * 1 -> 0 | L25: x | M25: Colony of Ubangi-Shari | N25: Abiras | O25: 24
A26: CHD_1960 | B26: Chad | C26: 19600811 | D26: 20261231 | E26: #66c2a5 | F26: Sovereign | H26: Africa | I26: CHD_1900_FRA | J26: =IF( F26 = "Sovereign", "x", "" ) -> x | K26: =( $C26<=$Q$1 )*( $D26 > $Q$1 ) * 1 -> 1 | L26: x | N26: N'Djamena | O26: 25
A27: CHD_1900_FRA | B27: French Chad | C27: 19000905 | D27: 19100115 | E27: #BFE6FF | F27: Dependent | G27: France | H27: Africa | I27: NA | J27: =IF( F27 = "Sovereign", "x", "" ) | K27: =( $C27<=$Q$1 )*( $D27 > $Q$1 ) * 1 -> 0 | L27: x | O27: 26
A28: CPV_1975 | B28: Cape Verde | C28: 19750705 | D28: 20261231 | E28: #fc8d62 | F28: Sovereign | H28: Africa | I28: CPV_1462_POR | J28: =IF( F28 = "Sovereign", "x", "" ) -> x | K28: =( $C28<=$Q$1 )*( $D28 > $Q$1 ) * 1 -> 1 | L28: x | M28: Republic of Cabo Verde | N28: Praia | O28: 27
A29: CPV_1462_POR | B29: Cape Verde | C29: 14620101 | D29: 19750705 | E29: #C98DE2 | F29: Dependent | G29: Portugal | H29: Africa | I29: NA | J29: =IF( F29 = "Sovereign", "x", "" ) | K29: =( $C29<=$Q$1 )*( $D29 > $Q$1 ) * 1 -> 0 | L29: x | M29: Overseas Province of Cape Verde | N29: Praia | O29: 28
A30: MRT_1960 | B30: Mauritania | C30: 19601128 | D30: 20261231 | E30: #8da0cb | F30: Sovereign | H30: Africa | I30: MRT_1958_FRA | J30: =IF( F30 = "Sovereign", "x", "" ) -> x | K30: =( $C30<=$Q$1 )*( $D30 > $Q$1 ) * 1 -> 1 | M30: Islamic Republic of Mauritania | N30: Nuoakchott | O30: 29
A31: MRT_1958_FRA | B31: French Mauritania | C31: 19581128 | D31: 19601128 | E31: #BFE6FF | F31: Dependent | G31: France | H31: Africa | I31: FWA_1895_FRA | J31: =IF( F31 = "Sovereign", "x", "" ) | K31: =( $C31<=$Q$1 )*( $D31 > $Q$1 ) * 1 -> 0 | M31: Islamic Republic of Mauritania | N31: Nuoakchott | O31: 30
A32: FWA_1895_FRA | B32: French West Africa | C32: 18951027 | D32: 19581218 | E32: #BFE6FF | F32: Dependent | G32: France | H32: Africa | I32: GUI_1891_FRA/MAL_1890_FRA/IVC_1893_FRA | J32: =IF( F32 = "Sovereign", "x", "" ) | K32: =( $C32<=$Q$1 )*( $D32 > $Q$1 ) * 1 -> 0 | M32: French West Africa | N32: Saint Louis | O32: 31
A33: MLF_1960 | B33: Mali Federation | C33: 19600620 | D33: 19600820 | E33: #e78ac3 | F33: Sovereign | H33: Africa | I33: MAL_1958_FRA/SEN_1958_FRA | J33: =IF( F33 = "Sovereign", "x", "" ) -> x | K33: =( $C33<=$Q$1 )*( $D33 > $Q$1 ) * 1 -> 0 | M33: Mali Federation | N33: Dakar | O33: 32
A34: SEN_1960 | B34: Senegal | C34: 19600820 | D34: 20261231 | E34: #a6d854 | F34: Sovereign | H34: Africa | I34: MLF_1960 | J34: =IF( F34 = "Sovereign", "x", "" ) -> x | K34: =( $C34<=$Q$1 )*( $D34 > $Q$1 ) * 1 -> 1 | M34: Republic of Senegal | N34: Dakar | O34: 33
A35: SEN_1958_FRA | B35: French Senegal | C35: 19581125 | D35: 19600620 | E35: #BFE6FF | F35: Dependent | G35: France | H35: Africa | I35: FWA_1895_FRA | J35: =IF( F35 = "Sovereign", "x", "" ) | K35: =( $C35<=$Q$1 )*( $D35 > $Q$1 ) * 1 -> 0 | M35: Republic of Senegal | N35: Dakar | O35: 34
A36: GAM_1965 | B36: The Gambia | C36: 19650218 | D36: 20261231 | E36: #ffd92f | F36: Sovereign | H36: Africa | I36: GAM_1816_UK | J36: =IF( F36 = "Sovereign", "x", "" ) -> x | K36: =( $C36<=$Q$1 )*( $D36 > $Q$1 ) * 1 -> 1 | M36: Republic of the Gambia | N36: Banjul | O36: 35
A37: GAM_1816_UK | B37: The Gambia | C37: 18161017 | D37: 19650218 | E37: #FFEEBA | F37: Dependent | G37: United Kingdom | H37: Africa | I37: NA | J37: =IF( F37 = "Sovereign", "x", "" ) | K37: =( $C37<=$Q$1 )*( $D37 > $Q$1 ) * 1 -> 0 | M37: Gambia Colony and Protectorate | N37: Bathurst | O37: 36
A38: GUI_1958 | B38: Guinea | C38: 19581002 | D38: 20261231 | E38: #e5c494 | F38: Sovereign | H38: Africa | I38: FWA_1895_FRA | J38: =IF( F38 = "Sovereign", "x", "" ) -> x | K38: =( $C38<=$Q$1 )*( $D38 > $Q$1 ) * 1 -> 1 | M38: Republic of Guinea | N38: Conakry | O38: 37
A39: GUI_1891_FRA | B39: French Guinea | C39: 18910101 | D39: 18951027 | E39: #BFE6FF | F39: Dependent | G39: France | H39: Africa | I39: NA | J39: =IF( F39 = "Sovereign", "x", "" ) | K39: =( $C39<=$Q$1 )*( $D39 > $Q$1 ) * 1 -> 0 | M39: Republic of Guinea | N39: Conakry | O39: 38
A40: GBS_1974 | B40: Guinea-Bissau | C40: 19740910 | D40: 20261231 | E40: #e41a1c | F40: Sovereign | H40: Africa | I40: GBS_1879_POR | J40: =IF( F40 = "Sovereign", "x", "" ) -> x | K40: =( $C40<=$Q$1 )*( $D40 > $Q$1 ) * 1 -> 1 | M40: Republic of Guinea-Bissau | N40: Bissau | O40: 39
...

Sheet Capitals
A1: ID | B1: Begin | C1: End | D1: Capital | E1: Lat | F1: Lon | G1: Wiki Coords | H1: Checked
A2: DJI_1977 | B2: 19770627 | C2: 20261231 | D2: Djibouti | E2: =11+36/60 -> 11.6 | F2: =43+10/60 -> 43.166667 | G2: 11°36′N 43°10′E | H2: =VLOOKUP( $A2, Sovereignty!$A$2:$L$510, 12, 0 ) -> x
A3: DJI_1862_FRA | B3: 19670705 | C3: 19770627 | D3: Djibouti | E3: =11+36/60 -> 11.6 | F3: =43+10/60 -> 43.166667 | G3: 11°36′N 43°10′E | H3: =VLOOKUP( $A3, Sovereignty!$A$2:$L$510, 12, 0 ) -> x
A4: DJI_1862_FRA | B4: 18960520 | C4: 19670705 | D4: Djibouti | E4: =11+36/60 -> 11.6 | F4: =43+10/60 -> 43.166667 | G4: 11°36′N 43°10′E | H4: =VLOOKUP( $A4, Sovereignty!$A$2:$L$510, 12, 0 ) -> x
A5: DJI_1862_FRA | B5: 18620311 | C5: 18960520 | D5: Obock | E5: =11+58/60 -> 11.966667 | F5: =43+17/60 -> 43.283333 | G5: 11°58′N 43°17′E | H5: =VLOOKUP( $A5, Sovereignty!$A$2:$L$510, 12, 0 ) -> x
A6: SOM_1960 | B6: 19600626 | C6: 20261231 | D6: Mogadishu | E6: =2+2/60+21/3600 -> 2.0391667 | F6: =45+20/60+31/3600 -> 45.341944 | G6: 02°02′21″N 45°20′31″E | H6: =VLOOKUP( $A6, Sovereignty!$A$2:$L$510, 12, 0 ) -> x
A7: SOL_1884_UK | B7: 18840101 | C7: 19410315 | D7: Berbera | E7: =10+26/60+8/3600 -> 10.435556 | F7: =45+59/3600 -> 45.016389 | G7: 10°26′08″N 045°00′59″E | H7: =VLOOKUP( $A7, Sovereignty!$A$2:$L$510, 12, 0 ) -> x
A8: SOL_1884_UK | B8: 19410315 | C8: 19600626 | D8: Hergeisa | E8: =9+33/60+40/3600 -> 9.5611111 | F8: =44+4/60 -> 44.066667 | G8: 9°33′40″N 44°04′00″E | H8: =VLOOKUP( $A8, Sovereignty!$A$2:$L$510, 12, 0 ) -> x
A9: SOM_1950_ITA | B9: 19500401 | C9: 19600701 | D9: Mogadishu | E9: =2+2/60+21/3600 -> 2.0391667 | F9: =45+20/60+31/3600 -> 45.341944 | G9: 02°02′21″N 45°20′31″E | H9: =VLOOKUP( $A9, Sovereignty!$A$2:$L$510, 12, 0 ) -> x
A10: SOM_1941_UK | B10: 19410225 | C10: 19500401 | D10: Mogadishu | E10: =2+2/60+21/3600 -> 2.0391667 | F10: =45+20/60+31/3600 -> 45.341944 | G10: 02°02′21″N 45°20′31″E | H10: =VLOOKUP( $A10, Sovereignty!$A$2:$L$510, 12, 0 ) -> x
A11: IEA_1936_ITA | B11: 19360509 | C11: 19411127 | D11: Addis Ababa | E11: =9+1/60+48/3600 -> 9.03 | F11: =38+44/60+24/3600 -> 38.74 | G11: 9°1′48″N 38°44′24″E | H11: =VLOOKUP( $A11, Sovereignty!$A$2:$L$510, 12, 0 ) -> x
A12: SOM_1889_ITA | B12: 18890208 | C12: 19360601 | D12: Mogadishu | E12: =2+2/60+21/3600 -> 2.0391667 | F12: =45+20/60+31/3600 -> 45.341944 | G12: 02°02′21″N 45°20′31″E | H12: =VLOOKUP( $A12, Sovereignty!$A$2:$L$510, 12, 0 ) -> x
A13: ERI_1993 | B13: 19930524 | C13: 20261231 | D13: Asmara | E13: =15+20/60+9/3600 -> 15.335833 | F13: =38+56/60+28/3600 -> 38.941111 | G13: 15°20′09″N 38°56′28″E | H13: =VLOOKUP( $A13, Sovereignty!$A$2:$L$510, 12, 0 ) -> x
A14: ERI_1952 | B14: 19520915 | C14: 19621114 | D14: Asmara | E14: =15+20/60+9/3600 -> 15.335833 | F14: =38+56/60+28/3600 -> 38.941111 | G14: 15°20′09″N 38°56′28″E | H14: =VLOOKUP( $A14, Sovereignty!$A$2:$L$510, 12, 0 ) -> x
A15: ERI_1941_UK | B15: 19411127 | C15: 19520915 | D15: Asmara | E15: =15+20/60+9/3600 -> 15.335833 | F15: =38+56/60+28/3600 -> 38.941111 | G15: 15°20′09″N 38°56′28″E | H15: =VLOOKUP( $A15, Sovereignty!$A$2:$L$510, 12, 0 ) -> x
A16: ERI_1882_ITA | B16: 18820705 | C16: 19360601 | D16: Asmara | E16: =15+20/60+9/3600 -> 15.335833 | F16: =38+56/60+28/3600 -> 38.941111 | G16: 15°20′09″N 38°56′28″E | H16: =VLOOKUP( $A16, Sovereignty!$A$2:$L$510, 12, 0 ) -> x
A17: ETH_1941 | B17: 19411127 | C17: 20261231 | D17: Addis Ababa | E17: =9+1/60+48/3600 -> 9.03 | F17: =38+44/60+24/3600 -> 38.74 | G17: 9°1′48″N 38°44′24″E | H17: =VLOOKUP( $A17, Sovereignty!$A$2:$L$510, 12, 0 ) -> x
A18: ETH_1855 | B18: 18890101 | C18: 19360509 | D18: Addis Ababa | E18: =9+1/60+48/3600 -> 9.03 | F18: =38+44/60+24/3600 -> 38.74 | G18: 9°1′48″N 38°44′24″E | H18: =VLOOKUP( $A18, Sovereignty!$A$2:$L$510, 12, 0 ) -> x
A19: ETH_1855 | B19: 18810101 | C19: 18890101 | D19: Mekelle | E19: =13+29/60+49/3600 -> 13.496944 | F19: =39+28/60+37/3600 -> 39.476944 | G19: 13°29′49″N 39°28′37″E | H19: =VLOOKUP( $A19, Sovereignty!$A$2:$L$510, 12, 0 ) -> x
A20: ETH_1855 | B20: 18550211 | C20: 18810101 | D20: Debre Tabor | E20: =11+51/60 -> 11.85 | F20: =38+1/60 -> 38.016667 | G20: 11°51′N 38°1′E | H20: =VLOOKUP( $A20, Sovereignty!$A$2:$L$510, 12, 0 ) -> x
A21: CON_1960 | B21: 19600815 | C21: 20261231 | D21: Brazzaville | E21: =-4-16/60 -> -4.2666667 | F21: =15+16/60 -> 15.266667 | G21: 4°16′S 15°16′E | H21: =VLOOKUP( $A21, Sovereignty!$A$2:$L$510, 12, 0 ) -> x
A22: CON_1958_FRA | B22: 19581128 | C22: 19600815 | D22: Brazzaville | E22: =-4-16/60 -> -4.2666667 | F22: =15+16/60 -> 15.266667 | G22: 4°16′S 15°16′E | H22: =VLOOKUP( $A22, Sovereignty!$A$2:$L$510, 12, 0 ) -> x
A23: FEA_1910_FRA | B23: 19100115 | C23: 19581128 | D23: Brazzaville | E23: =-4-16/60 -> -4.2666667 | F23: =15+16/60 -> 15.266667 | G23: 4°16′S 15°16′E | H23: =VLOOKUP( $A23, Sovereignty!$A$2:$L$510, 12, 0 ) -> x
A24: CON_1882_FRA | B24: 18821130 | C24: 19100115 | D24: Brazzaville | E24: =-4-16/60 -> -4.2666667 | F24: =15+16/60 -> 15.266667 | G24: 4°16′S 15°16′E | H24: =VLOOKUP( $A24, Sovereignty!$A$2:$L$510, 12, 0 ) -> x
A25: GAB_1960 | B25: 19600817 | C25: 20261231 | D25: Libreville | E25: =24/60+38/3600 -> 0.41055556 | F25: =9+26/60+25/3600 -> 9.4402778 | G25: 0°24′28″N 9°26′25″E | H25: =VLOOKUP( $A25, Sovereignty!$A$2:$L$510, 12, 0 ) -> x
A26: GAB_1958_FRA | B26: 19581128 | C26: 19600817 | D26: Libreville | E26: =24/60+38/3600 -> 0.41055556 | F26: =9+26/60+25/3600 -> 9.4402778 | G26: 0°24′28″N 9°26′25″E | H26: =VLOOKUP( $A26, Sovereignty!$A$2:$L$510, 12, 0 ) -> x
A27: GAB_1885_FRA | B27: 18880101 | C27: 19100115 | D27: Libreville | E27: =24/60+38/3600 -> 0.41055556 | F27: =9+26/60+25/3600 -> 9.4402778 | G27: 0°24′28″N 9°26′25″E | H27: =VLOOKUP( $A27, Sovereignty!$A$2:$L$510, 12, 0 ) -> x
A28: CAR_1960 | B28: 19600813 | C28: 20261231 | D28: Bangui | E28: =4+22/60+24/3600 -> 4.3733333 | F28: =18+33/60+46/3600 -> 18.562778 | G28: 04°22′24″N 18°33′46″E | H28: =VLOOKUP( $A28, Sovereignty!$A$2:$L$510, 12, 0 ) -> x
A29: CAR_1958_FRA | B29: 19581201 | C29: 19600813 | D29: Bangui | E29: =4+22/60+24/3600 -> 4.3733333 | F29: =18+33/60+46/3600 -> 18.562778 | G29: 04°22′24″N 18°33′46″E | H29: =VLOOKUP( $A29, Sovereignty!$A$2:$L$510, 12, 0 ) -> x
A30: CAR_1903_FRA | B30: 19061211 | C30: 19100115 | D30: Bangui | E30: =4+22/60+24/3600 -> 4.3733333 | F30: =18+33/60+46/3600 -> 18.562778 | G30: 04°22′24″N 18°33′46″E | H30: =VLOOKUP( $A30, Sovereignty!$A$2:$L$510, 12, 0 ) -> x
A31: CAR_1903_FRA | B31: 19060210 | C31: 19061211 | D31: Fort de Passel | E31: =5+1/60+29.7/3600 -> 5.0249167 | F31: =19+15/60+30.9/3600 -> 19.258583 | G31: 5°1′29.7″N 19°15′30.9″E | H31: =VLOOKUP( $A31, Sovereignty!$A$2:$L$510, 12, 0 ) -> x
A32: CAR_1903_FRA | B32: 19031229 | C32: 19060210 | D32: Abiras | E32: =4.135 -> 4.135 | F32: =22.44 -> 22.44 | G32: 4.135°N 22.440°E | H32: =VLOOKUP( $A32, Sovereignty!$A$2:$L$510, 12, 0 ) -> x
A33: CHD_1960 | B33: 19730406 | C33: 20261231 | D33: N'Djamena | E33: =12+6/60+19/3600 -> 12.105278 | F33: =15+2/60+41/3600 -> 15.044722 | G33: 12°06′19″N 15°02′41″E | H33: =VLOOKUP( $A33, Sovereignty!$A$2:$L$510, 12, 0 ) -> x
A34: CHD_1960 | B34: 19600811 | C34: 19730406 | D34: Fort Lamy | E34: =12+6/60+19/3600 -> 12.105278 | F34: =15+2/60+41/3600 -> 15.044722 | G34: 12°06′19″N 15°02′41″E | H34: =VLOOKUP( $A34, Sovereignty!$A$2:$L$510, 12, 0 ) -> x
A35: CHD_1900_FRA | B35: 19000905 | C35: 19100115 | D35: Fort Lamy | E35: =12+6/60+19/3600 -> 12.105278 | F35: =15+2/60+41/3600 -> 15.044722 | G35: 12°06′19″N 15°02′41″E | H35: =VLOOKUP( $A35, Sovereignty!$A$2:$L$510, 12, 0 ) -> x
A36: CHD_1958_FRA | B36: 19581128 | C36: 19600811 | D36: Fort Lamy | E36: =12+6/60+19/3600 -> 12.105278 | F36: =15+2/60+41/3600 -> 15.044722 | G36: 12°06′19″N 15°02′41″E | H36: =VLOOKUP( $A36, Sovereignty!$A$2:$L$510, 12, 0 ) -> x
A37: CPV_1975 | B37: 19750705 | C37: 20261231 | D37: Praia | E37: =14.918 -> 14.918 | F37: =-23.509 -> -23.509 | G37: 14.918°N 23.509°W | H37: =VLOOKUP( $A37, Sovereignty!$A$2:$L$510, 12, 0 ) -> x
A38: CPV_1462_POR | B38: 14620101 | C38: 19750705 | D38: Praia | E38: =14.918 -> 14.918 | F38: =-23.509 -> -23.509 | G38: 14.918°N 23.509°W | H38: =VLOOKUP( $A38, Sovereignty!$A$2:$L$510, 12, 0 ) -> x
A39: MRT_1960 | B39: 19601128 | C39: 20261231 | D39: Nouakchott | E39: =18+5/60+7/3600 -> 18.085278 | F39: =-15-58/60-21/3600 -> -15.9725 | G39: 18°05′07″N 15°58′21″W | H39: =VLOOKUP( $A39, Sovereignty!$A$2:$L$510, 12, 0 ) -> 0
A40: MRT_1958_FRA | B40: 19581128 | C40: 19601128 | D40: Nouakchott | E40: =18+5/60+7/3600 -> 18.085278 | F40: =-15-58/60-21/3600 -> -15.9725 | G40: 18°05′07″N 15°58′21″W | H40: =VLOOKUP( $A40, Sovereignty!$A$2:$L$510, 12, 0 ) -> 0
...

Sheet Names
A1: ID | B1: Begin | C1: End | D1: DisplayName | E1: OfficialName | F1: Checked
A2: DJI_1977 | B2: 19770627 | C2: 20261231 | D2: Djibouti | E2: Republic of Djibouti | F2: =VLOOKUP( $A2, Sovereignty!$A$2:$L$510, 12, 0 ) -> x
A3: DJI_1862_FRA | B3: 19670705 | C3: 19770627 | D3: Afars and Issas | E3: French Territory of the Afars and the Issas | F3: =VLOOKUP( $A3, Sovereignty!$A$2:$L$510, 12, 0 ) -> x
A4: DJI_1862_FRA | B4: 18960520 | C4: 19670705 | D4: French Somaliland | E4: French Somaliland | F4: =VLOOKUP( $A4, Sovereignty!$A$2:$L$510, 12, 0 ) -> x
A5: DJI_1862_FRA | B5: 18620311 | C5: 18960520 | D5: Obock Territory | E5: Obock Territory and Dependencies | F5: =VLOOKUP( $A5, Sovereignty!$A$2:$L$510, 12, 0 ) -> x
A6: SOM_1960 | B6: 19600626 | C6: 20261231 | D6: Somalia | E6: Federal Republic of Somalia | F6: =VLOOKUP( $A6, Sovereignty!$A$2:$L$510, 12, 0 ) -> x
A7: SOL_1884_UK | B7: 18840101 | C7: 19600626 | D7: British Somaliland | E7: Somaliland Protectorate | F7: =VLOOKUP( $A7, Sovereignty!$A$2:$L$510, 12, 0 ) -> x
A8: SOM_1950_ITA | B8: 19500401 | C8: 19600701 | D8: Somaliland | E8: Trust Territory of Somaliland | F8: =VLOOKUP( $A8, Sovereignty!$A$2:$L$510, 12, 0 ) -> x
A9: SOM_1941_UK | B9: 19411127 | C9: 19500401 | D9: Somaliland | E9: British Military Administration of Somaliland | F9: =VLOOKUP( $A9, Sovereignty!$A$2:$L$510, 12, 0 ) -> x
A10: IEA_1936_ITA | B10: 19360509 | C10: 19411127 | D10: Italian East Africa | E10: Italian East Africa | F10: =VLOOKUP( $A10, Sovereignty!$A$2:$L$510, 12, 0 ) -> x
A11: SOM_1889_ITA | B11: 18890208 | C11: 19360601 | D11: Italian Somaliland | E11: Italian Somaliland | F11: =VLOOKUP( $A11, Sovereignty!$A$2:$L$510, 12, 0 ) -> x
A12: ERI_1993 | B12: 19930524 | C12: 20261231 | D12: Eritrea | E12: State of Eritrea | F12: =VLOOKUP( $A12, Sovereignty!$A$2:$L$510, 12, 0 ) -> x
A13: ERI_1952 | B13: 19520915 | C13: 19621114 | D13: Eritrea | E13: Eritrea | F13: =VLOOKUP( $A13, Sovereignty!$A$2:$L$510, 12, 0 ) -> x
... A610: SEI_1571_SPA | B610: 15710101 | C610: 18981210 | D610: Spanish East Indies | E610: Spanish East Indies | F610: =VLOOKUP( $A610, Sovereignty!$A$2:$L$510, 12, 0 ) -> 0

Sheet Maps
A1: ID | B1: Begin | C1: End | D1: Map | E1: Checked | F1: Mapped | G1: Notes | J1: Made
A2: DJI_1977 | B2: 19770627 | C2: 20261231 | D2: Djibouti | E2: =VLOOKUP( $A2, Sovereignty!$A$2:$L$510, 12, 0 ) -> x
A3: DJI_1862_FRA | B3: 18960520 | C3: 19770627 | D3: Djibouti | E3: =VLOOKUP( $A3, Sovereignty!$A$2:$L$510, 12, 0 ) -> x
A4: DJI_1862_FRA | B4: 18620311 | C4: 18960520 | D4: Obock | E4: =VLOOKUP( $A4, Sovereignty!$A$2:$L$510, 12, 0 ) -> x | I4: Algeria | J4: x
A5: SOM_1960 | B5: 19600701 | C5: 20261231 | D5: BrSomaliaItSomalia | E5: =VLOOKUP( $A5, Sovereignty!$A$2:$L$510, 12, 0 ) -> x | I5: Angola | J5: x
A6: SOM_1960 | B6: 19600626 | C6: 19600701 | D6: BrSomalia | E6: =VLOOKUP( $A6, Sovereignty!$A$2:$L$510, 12, 0 ) -> x | I6: BC1BC2FC | J6: x
A7: SOL_1884_UK | B7: 18840101 | C7: 19600626 | D7: BrSomalia | E7: =VLOOKUP( $A7, Sovereignty!$A$2:$L$510, 12, 0 ) -> x | I7: Benin | J7: x
A8: SOM_1950_ITA | B8: 19500401 | C8: 19600701 | D8: ItSomalia | E8: =VLOOKUP( $A8, Sovereignty!$A$2:$L$510, 12, 0 ) -> x | I8: BenIvcMauNigBur | J8: x
A9: SOM_1941_UK | B9: 19411127 | C9: 19500401 | D9: ItSomalia | E9: =VLOOKUP( $A9, Sovereignty!$A$2:$L$510, 12, 0 ) -> x | I9: BenIvcNigBur | J9: x
A10: IEA_1936_ITA | B10: 19410225 | C10: 19411127 | D10: EthiopiaEritrea | E10: =VLOOKUP( $A10, Sovereignty!$A$2:$L$510, 12, 0 ) -> x | I10: Botswana | J10: x
A11: IEA_1936_ITA | B11: 19360601 | C11: 19410225 | D11: EthiopiaEritreaItSomalia | E11: =VLOOKUP( $A11, Sovereignty!$A$2:$L$510, 12, 0 ) -> x | I11: BritishCameroon | J11: x
A12: IEA_1936_ITA | B12: 19360509 | C12: 19360601 | D12: Ethiopia | E12: =VLOOKUP( $A12, Sovereignty!$A$2:$L$510, 12, 0 ) -> x | I12: BrSomalia | J12: x
A13: SOM_1889_ITA | B13: 18890208 | C13: 19360601 | D13: ItSomalia | E13: =VLOOKUP( $A13, Sovereignty!$A$2:$L$510, 12, 0 ) -> x | I13: BrSomaliaItSomalia | J13: x
A14: ERI_1993 | B14: 19930524 | C14: 20261231 | D14: Eritrea | E14: =VLOOKUP( $A14, Sovereignty!$A$2:$L$510, 12, 0 ) -> x | I14: BurkinaFaso | J14: x
A15: ERI_1952 | B15: 19520915 | C15: 19621114 | D15: Eritrea | E15: =VLOOKUP( $A15, Sovereignty!$A$2:$L$510, 12, 0 ) -> x | I15: Burundi | J15: x
... A100: CAM_1916_UK | B100: 19160720 | C100: 19611001 | D100: BritishCameroon | E100: =VLOOKUP( $A100, Sovereignty!$A$2:$L$510, 12, 0 ) -> 0 | I100: Zimbabwe | J100: x
A101: CAM_1916_FRA | B101: 19160720 | C101: 19601001 | D101: FrenchCameroon | E101: =VLOOKUP( $A101, Sovereignty!$A$2:$L$510, 12, 0 ) -> 0
A102: CAM_1884_GER | B102: 18840817 | C102: 19160720 | D102: BC1BC2FC | E102: =VLOOKUP( $A102, Sovereignty!$A$2:$L$510, 12, 0 ) -> 0
A103: NAM_1990 | B103: 19900321 | C103: 20261231 | D103: Namibia | E103: =VLOOKUP( $A103, Sovereignty!$A$2:$L$510, 12, 0 ) -> 0
A104: SWA_1915_SA | B104: 19150709 | C104: 19900321 | D104: Namibia | E104: =VLOOKUP( $A104, Sovereignty!$A$2:$L$510, 12, 0 ) -> 0
A105: SWA_1884_GER | B105: 18840807 | C105: 19150709 | D105: Namibia | E105: =VLOOKUP( $A105, Sovereignty!$A$2:$L$510, 12, 0 ) -> 0
A106: BOT_1966 | B106: 19660930 | C106: 20261231 | D106: Botswana | E106: =VLOOKUP( $A106, Sovereignty!$A$2:$L$510, 12, 0 ) -> 0
A107: BOT_1885_UK | B107: 18850331 | C107: 19660930 | D107: Botswana | E107: =VLOOKUP( $A107, Sovereignty!$A$2:$L$510, 12, 0 ) -> 0
A108: SAF_1910 | B108: 19100531 | C108: 20261231 | D108: SouthAfrica | E108: =VLOOKUP( $A108, Sovereignty!$A$2:$L$510, 12, 0 ) -> 0
A109: ESW_1968 | B109: 19680924 | C109: 20261231 | D109: Eswatini | E109: =VLOOKUP( $A109, Sovereignty!$A$2:$L$510, 12, 0 ) -> 0
A110: ESW_1903_UK | B110: 19030101 | C110: 19680924 | D110: Eswatini | E110: =VLOOKUP( $A110, Sovereignty!$A$2:$L$510, 12, 0 ) -> 0
A111: NAT_1843_UK | B111: 18430504 | C111: 19100531 | D111: Natal | E111: =VLOOKUP( $A111, Sovereignty!$A$2:$L$510, 12, 0 ) -> 0
A112: LES_1966 | B112: 19661004 | C112: 20261231 | D112: Lesotho | E112: =VLOOKUP( $A112, Sovereignty!$A$2:$L$510, 12, 0 ) -> 0
... A181: ALG_1516_OTT | B181: 15160101 | C181: 18300705 | D181: Algeria | E181: =VLOOKUP( $A181, Sovereignty!$A$2:$L$510, 12, 0 ) -> 0
A182: BRA_1822 | B182: 18220907 | C182: 20261231 | D182: ModernBrazil | E182: =VLOOKUP( $A182, Sovereignty!$A$2:$L$510, 12, 0 ) -> x | F182: x | G182: x | I182: Ar2Bo2 | J182: x
A183: BRA_1815 | B183: 18151216 | C183: 18220907 | D183: ModernBrazil | E183: =VLOOKUP( $A183, Sovereignty!$A$2:$L$510, 12, 0 ) -> x | F183: x | G183: x | I183: Ar2Bo2UruPar | J183: x
A184: BRA_1549_POR | B184: 15490101 | C184: 18151216 | D184: ModernBrazil | E184: =VLOOKUP( $A184, Sovereignty!$A$2:$L$510, 12, 0 ) -> x | F184: x | G184: x | I184: Ar2Bo2UruParPer | J184: x
A185: URU_1825 | B185: 18250825 | C185: 20261231 | D185: ModernUruguay | E185: =VLOOKUP( $A185, Sovereignty!$A$2:$L$510, 12, 0 ) -> x | F185: x | G185: x | I185: VicePeru | J185: x
A186: URU_1817_BRA | B186: 18170120 | C186: 18250825 | D186: ModernUruguay | E186: =VLOOKUP( $A186, Sovereignty!$A$2:$L$510, 12, 0 ) -> x | F186: x | G186: x | I186: Ar2Bo2Uru | J186: x
A187: UPR_1810 | B187: 18110514 | C187: 18160709 | D187: Ar2Bo2Uru | E187: =VLOOKUP( $A187, Sovereignty!$A$2:$L$510, 12, 0 ) -> x | F187: x | G187: x | I187: ModernArgentina | J187: x
A188: UPR_1810 | B188: 18100525 | C188: 18110514 | D188: Ar2Bo2ParUru | E188: =VLOOKUP( $A188, Sovereignty!$A$2:$L$510, 12, 0 ) -> x | F188: x | G188: x | I188: RumpArgentina | J188: x
A189: UPR_1776_SPA | B189: 17760801 | C189: 18100525 | D189: Ar2Bo2ParUru | E189: =VLOOKUP( $A189, Sovereignty!$A$2:$L$510, 12, 0 ) -> x | F189: x | G189: x | I189: ModernBolivia | J189: x
A190: PAR_1811 | B190: 18110514 | C190: 20261231 | D190: ModernParaguay | E190: =VLOOKUP( $A190, Sovereignty!$A$2:$L$510, 12, 0 ) -> x | F190: x | G190: x | I190: SeaBolivia | J190: x
A191: ARG_1816 | B191: 18830101 | C191: 20261231 | D191: ModernArgentina | E191: =VLOOKUP( $A191, Sovereignty!$A$2:$L$510, 12, 0 ) -> x | F191: x | G191: x | I191: ModernBrazil | J191: x
A192: ARG_1816 | B192: 18250806 | C192: 18830101 | D192: RumpArgentina | E192: =VLOOKUP( $A192, Sovereignty!$A$2:$L$510, 12, 0 ) -> x | F192: x | G192: x | I192: ColEcuPan | J192: x
...
